Workbook

Sheet Consolidado
A1: Aplicativo | B1: Producto | C1: Filtros | D1: Moneda | E1: Saldo Aplicativo sin Filtro | F1: Saldo Aplicativo con Filtro y agrupaciones | G1: Saldos Finanzas | H1: Ajuste RCD | I1: Saldos Contables | J1: Diff Sal.Fin vs (Sal.Apr S.F + Ajus.RCD) | K1: % de cuadre Sal.Fin vs (Sal.Apr S.F + Ajus.RCD) | L1: Diff Sal.Fin vs (Sal.Apr C.F + Ajus.RCD) | M1: % de cuadre Sal.Fin vs (Sal.Apr C.F + Ajus.RCD) | N1: Diff Sal.Cont vs (Sal.Apr C.F + Ajus.RCD) | O1: % de cuadre Sal.Cont vs (Sal.Apr C.F + Ajus.RCD) | P1: Comentarios
A2: $IM | B2: Cuentas Corrientes | C2: CASE WHEN P01_ID_APLI = '$IM' AND SUBSTR(P01_CT_CONT1_MTR, 1, 6) IN ('810402', '810409') THEN 1 ELSE 0 END FLGACU_IM_CTA CASE WHEN P01_ID_APLI IN ('$IM', '$ST') AND NOT (NVL(P01_RUBRO, ' ') IN ('01', '03') AND P01_NU_SECU < 2) THEN 1 ELSE 0 END FLGACU_IM_ST, /*FILTRO 11: Registros de $IM y $ST*/ | D2: PSS | E2: =SUMIFS(Detalle!$E$2:$E$940,Detalle!$A$2:$A$940,Consolidado!A2,Detalle!$D$2:$D$940,Consolidado!D2) -> 8.8649504e+09 | F2: =SUMIFS(Detalle!$F$2:$F$940,Detalle!$A$2:$A$940,Consolidado!A2,Detalle!$D$2:$D$940,Consolidado!D2) -> 8.8649504e+09 | G2: =SUMIFS(Detalle!$G$2:$G$940,Detalle!$A$2:$A$940,Consolidado!A2,Detalle!$D$2:$D$940,Consolidado!D2) -> 8.8649504e+09 | H2: =SUMIFS(Detalle!$H$2:$H$940,Detalle!$A$2:$A$940,Consolidado!A2,Detalle!$D$2:$D$940,Consolidado!D2) -> 0 | I2: =SUMIFS(Detalle!$I$2:$I$940,Detalle!$A$2:$A$940,Consolidado!A2,Detalle!$D$2:$D$940,Consolidado!D2) -> 8.8649501e+09 | J2: =G2-(E2+H2) -> 0 | K2: =1-ABS($G2-(E2+H2))/G2 -> 1 | L2: =G2-(F2+H2) -> 0 | M2: =1-ABS($G2-(F2+H2))/(G2) -> 1 | N2: =I2-(F2+H2) -> -320.88 | O2: =1-ABS($I2-(F2+H2))/I2 -> 0.99999996 | P2: 25/06: Parcialmente Sustentado
A3: $IM | B3: Cuentas Corrientes | C3: CASE WHEN P01_ID_APLI = '$IM' AND SUBSTR(P01_CT_CONT1_MTR, 1, 6) IN ('810402', '810409') THEN 1 ELSE 0 END FLGACU_IM_CTA CASE WHEN P01_ID_APLI IN ('$IM', '$ST') AND NOT (NVL(P01_RUBRO, ' ') IN ('01', '03') AND P01_NU_SECU < 2) THEN 1 ELSE 0 END FLGACU_IM_ST, /*FILTRO 11: Registros de $IM y $ST*/ | D3: USD | E3: =SUMIFS(Detalle!$E$2:$E$940,Detalle!$A$2:$A$940,Consolidado!A3,Detalle!$D$2:$D$940,Consolidado!D3) -> 1.4235015e+09 | F3: =SUMIFS(Detalle!$F$2:$F$940,Detalle!$A$2:$A$940,Consolidado!A3,Detalle!$D$2:$D$940,Consolidado!D3) -> 1.4235015e+09 | G3: =SUMIFS(Detalle!$G$2:$G$940,Detalle!$A$2:$A$940,Consolidado!A3,Detalle!$D$2:$D$940,Consolidado!D3) -> 1.423501e+09 | H3: =SUMIFS(Detalle!$H$2:$H$940,Detalle!$A$2:$A$940,Consolidado!A3,Detalle!$D$2:$D$940,Consolidado!D3) -> 0 | I3: =SUMIFS(Detalle!$I$2:$I$940,Detalle!$A$2:$A$940,Consolidado!A3,Detalle!$D$2:$D$940,Consolidado!D3) -> 1.4235011e+09 | J3: =G3-(E3+H3) -> -477.61 | K3: =1-ABS($G3-(E3+H3))/G3 -> 0.99999966 | L3: =G3-(F3+H3) -> -477.61 | M3: =1-ABS($G3-(F3+H3))/(G3) -> 0.99999966 | N3: =I3-(F3+H3) -> -377.7633 | O3: =1-ABS($I3-(F3+H3))/I3 -> 0.99999973 | P3: 25/06: Parcialmente Sustentado
A4: $ST | B4: Ahorro Plazo, Fijo, Certificados bancarios, etc | C4: CASE WHEN P01_ID_APLI IN ('$IM', '$ST') AND NOT (NVL(P01_RUBRO, ' ') IN ('01', '03') AND P01_NU_SECU < 2) THEN 1 ELSE 0 END FLGACU_IM_ST, /*FILTRO 11: Registros de $IM y $ST*/ | D4: PSS | E4: =SUMIFS(Detalle!$E$2:$E$940,Detalle!$A$2:$A$940,Consolidado!A4,Detalle!$D$2:$D$940,Consolidado!D4) -> 2.4027527e+10 | F4: =SUMIFS(Detalle!$F$2:$F$940,Detalle!$A$2:$A$940,Consolidado!A4,Detalle!$D$2:$D$940,Consolidado!D4) -> 2.2341549e+10 | G4: =SUMIFS(Detalle!$G$2:$G$940,Detalle!$A$2:$A$940,Consolidado!A4,Detalle!$D$2:$D$940,Consolidado!D4) -> 2.2341561e+10 | H4: =SUMIFS(Detalle!$H$2:$H$940,Detalle!$A$2:$A$940,Consolidado!A4,Detalle!$D$2:$D$940,Consolidado!D4) -> 0 | I4: =SUMIFS(Detalle!$I$2:$I$940,Detalle!$A$2:$A$940,Consolidado!A4,Detalle!$D$2:$D$940,Consolidado!D4) -> 2.2341549e+10 | J4: =G4-(E4+H4) -> -1.6859663e+09 | K4: =1-ABS($G4-(E4+H4))/G4 -> 0.92453677 | L4: =G4-(F4+H4) -> 11900 | M4: =1-ABS($G4-(F4+H4))/(G4) -> 0.99999947 | N4: =I4-(F4+H4) -> 61.999996 | O4: =1-ABS($I4-(F4+H4))/I4 -> 1 | P4: 25/06: Parcialmente Sustentado
A5: $ST | B5: Ahorro Plazo, Fijo, Certificados bancarios, etc | C5: CASE WHEN P01_ID_APLI IN ('$IM', '$ST') AND NOT (NVL(P01_RUBRO, ' ') IN ('01', '03') AND P01_NU_SECU < 2) THEN 1 ELSE 0 END FLGACU_IM_ST, /*FILTRO 11: Registros de $IM y $ST*/ | D5: USD | E5: =SUMIFS(Detalle!$E$2:$E$940,Detalle!$A$2:$A$940,Consolidado!A5,Detalle!$D$2:$D$940,Consolidado!D5) -> 3.2852278e+09 | F5: =SUMIFS(Detalle!$F$2:$F$940,Detalle!$A$2:$A$940,Consolidado!A5,Detalle!$D$2:$D$940,Consolidado!D5) -> 2.8833203e+09 | G5: =SUMIFS(Detalle!$G$2:$G$940,Detalle!$A$2:$A$940,Consolidado!A5,Detalle!$D$2:$D$940,Consolidado!D5) -> 2.8827101e+09 | H5: =SUMIFS(Detalle!$H$2:$H$940,Detalle!$A$2:$A$940,Consolidado!A5,Detalle!$D$2:$D$940,Consolidado!D5) -> 0 | I5: =SUMIFS(Detalle!$I$2:$I$940,Detalle!$A$2:$A$940,Consolidado!A5,Detalle!$D$2:$D$940,Consolidado!D5) -> 2.8827199e+09 | J5: =G5-(E5+H5) -> -4.0251773e+08 | K5: =1-ABS($G5-(E5+H5))/G5 -> 0.86036829 | L5: =G5-(F5+H5) -> -610266.48 | M5: =1-ABS($G5-(F5+H5))/(G5) -> 0.9997883 | N5: =I5-(F5+H5) -> -600405.28 | O5: =1-ABS($I5-(F5+H5))/I5 -> 0.99979172 | P5: 25/06: Parcialmente Sustentado
A6: CCD | B6: Core de Créditos Digital | C6: - | D6: PSS | E6: =SUMIFS(Detalle!$E$2:$E$940,Detalle!$A$2:$A$940,Consolidado!A6,Detalle!$D$2:$D$940,Consolidado!D6) -> 2676788.7 | F6: =SUMIFS(Detalle!$F$2:$F$940,Detalle!$A$2:$A$940,Consolidado!A6,Detalle!$D$2:$D$940,Consolidado!D6) -> 2676788.7 | G6: =SUMIFS(Detalle!$G$2:$G$940,Detalle!$A$2:$A$940,Consolidado!A6,Detalle!$D$2:$D$940,Consolidado!D6) -> 2676788.7 | H6: =SUMIFS(Detalle!$H$2:$H$940,Detalle!$A$2:$A$940,Consolidado!A6,Detalle!$D$2:$D$940,Consolidado!D6) -> 0 | I6: =SUMIFS(Detalle!$I$2:$I$940,Detalle!$A$2:$A$940,Consolidado!A6,Detalle!$D$2:$D$940,Consolidado!D6) -> 2676788.7 | J6: =G6-(E6+H6) -> 0 | K6: =1-ABS($G6-(E6+H6))/G6 -> 1 | L6: =G6-(F6+H6) -> 0 | M6: =1-ABS($G6-(F6+H6))/(G6) -> 1 | N6: =I6-(F6+H6) -> 0 | O6: =1-ABS($I6-(F6+H6))/I6 -> 1
A7: CDO | B7: Tarjetas | C7: - | D7: PSS | E7: =SUMIFS(Detalle!$E$2:$E$940,Detalle!$A$2:$A$940,Consolidado!A7,Detalle!$D$2:$D$940,Consolidado!D7) -> 5.1239313e+09 | F7: =SUMIFS(Detalle!$F$2:$F$940,Detalle!$A$2:$A$940,Consolidado!A7,Detalle!$D$2:$D$940,Consolidado!D7) -> 5.1239313e+09 | G7: =SUMIFS(Detalle!$G$2:$G$940,Detalle!$A$2:$A$940,Consolidado!A7,Detalle!$D$2:$D$940,Consolidado!D7) -> 5.1432622e+09 | H7: =SUMIFS(Detalle!$H$2:$H$940,Detalle!$A$2:$A$940,Consolidado!A7,Detalle!$D$2:$D$940,Consolidado!D7) -> 19330839 | I7: =SUMIFS(Detalle!$I$2:$I$940,Detalle!$A$2:$A$940,Consolidado!A7,Detalle!$D$2:$D$940,Consolidado!D7) -> 5.1432432e+09 | J7: =G7-(E7+H7) -> 0 | K7: =1-ABS($G7-(E7+H7))/G7 -> 1 | L7: =G7-(F7+H7) -> 0 | M7: =1-ABS($G7-(F7+H7))/(G7) -> 1 | N7: =I7-(F7+H7) -> -19016.75 | O7: =1-ABS($I7-(F7+H7))/I7 -> 0.9999963 | P7: 25/06: Parcialmente Sustentado
A8: CDO | B8: Tarjetas | C8: - | D8: USD | E8: =SUMIFS(Detalle!$E$2:$E$940,Detalle!$A$2:$A$940,Consolidado!A8,Detalle!$D$2:$D$940,Consolidado!D8) -> 1.386757e+08 | F8: =SUMIFS(Detalle!$F$2:$F$940,Detalle!$A$2:$A$940,Consolidado!A8,Detalle!$D$2:$D$940,Consolidado!D8) -> 1.386757e+08 | G8: =SUMIFS(Detalle!$G$2:$G$940,Detalle!$A$2:$A$940,Consolidado!A8,Detalle!$D$2:$D$940,Consolidado!D8) -> 1.3867348e+08 | H8: =SUMIFS(Detalle!$H$2:$H$940,Detalle!$A$2:$A$940,Consolidado!A8,Detalle!$D$2:$D$940,Consolidado!D8) -> 0 | I8: =SUMIFS(Detalle!$I$2:$I$940,Detalle!$A$2:$A$940,Consolidado!A8,Detalle!$D$2:$D$940,Consolidado!D8) -> 1.3867303e+08 | J8: =G8-(E8+H8) -> -2228.63 | K8: =1-ABS($G8-(E8+H8))/G8 -> 0.99998393 | L8: =G8-(F8+H8) -> -2228.63 | M8: =1-ABS($G8-(F8+H8))/(G8) -> 0.99998393 | N8: =I8-(F8+H8) -> -2677.0229 | O8: =1-ABS($I8-(F8+H8))/I8 -> 0.9999807 | P8: 25/06: Parcialmente Sustentado
A9: FCD | B9: Financiamiento y Cobranza de documentos | C9: CASE WHEN P01_ID_APLI IN ('$PR', 'FCD') AND NOT (NVL(P01_RUBRO, ' ') IN ('01', '18') OR NVL(P01_RUBRO, ' ') = '04' AND (NVL(P01_CO_PROD, ' ') IN ('304', '305') OR NVL(P01_CO_PROD, ' ') = '198' AND NVL(P01_CO_SUB_PROD, ' ') IN ('304', '305'))) THEN 1 ELSE 0 END FLGACU_PR_FCD, /*FILTRO 09: Registros de $PR y FCD*/ | D9: PSS | E9: =SUMIFS(Detalle!$E$2:$E$940,Detalle!$A$2:$A$940,Consolidado!A9,Detalle!$D$2:$D$940,Consolidado!D9) -> 1.2210675e+09 | F9: =SUMIFS(Detalle!$F$2:$F$940,Detalle!$A$2:$A$940,Consolidado!A9,Detalle!$D$2:$D$940,Consolidado!D9) -> 1.2210675e+09 | G9: =SUMIFS(Detalle!$G$2:$G$940,Detalle!$A$2:$A$940,Consolidado!A9,Detalle!$D$2:$D$940,Consolidado!D9) -> 1.2210675e+09 | H9: =SUMIFS(Detalle!$H$2:$H$940,Detalle!$A$2:$A$940,Consolidado!A9,Detalle!$D$2:$D$940,Consolidado!D9) -> 5.8207661e-11 | I9: =SUMIFS(Detalle!$I$2:$I$940,Detalle!$A$2:$A$940,Consolidado!A9,Detalle!$D$2:$D$940,Consolidado!D9) -> 1.2210675e+09 | J9: =G9-(E9+H9) -> 0 | K9: =1-ABS($G9-(E9+H9))/G9 -> 1 | L9: =G9-(F9+H9) -> 0 | M9: =1-ABS($G9-(F9+H9))/(G9) -> 1 | N9: =I9-(F9+H9) -> 0 | O9: =1-ABS($I9-(F9+H9))/I9 -> 1
A10: FCD | B10: Financiamiento y Cobranza de documentos | C10: CASE WHEN P01_ID_APLI IN ('$PR', 'FCD') AND NOT (NVL(P01_RUBRO, ' ') IN ('01', '18') OR NVL(P01_RUBRO, ' ') = '04' AND (NVL(P01_CO_PROD, ' ') IN ('304', '305') OR NVL(P01_CO_PROD, ' ') = '198' AND NVL(P01_CO_SUB_PROD, ' ') IN ('304', '305'))) THEN 1 ELSE 0 END FLGACU_PR_FCD, /*FILTRO 09: Registros de $PR y FCD*/ | D10: USD | E10: =SUMIFS(Detalle!$E$2:$E$940,Detalle!$A$2:$A$940,Consolidado!A10,Detalle!$D$2:$D$940,Consolidado!D10) -> 3.6335711e+08 | F10: =SUMIFS(Detalle!$F$2:$F$940,Detalle!$A$2:$A$940,Consolidado!A10,Detalle!$D$2:$D$940,Consolidado!D10) -> 3.6335711e+08 | G10: =SUMIFS(Detalle!$G$2:$G$940,Detalle!$A$2:$A$940,Consolidado!A10,Detalle!$D$2:$D$940,Consolidado!D10) -> 3.6326913e+08 | H10: =SUMIFS(Detalle!$H$2:$H$940,Detalle!$A$2:$A$940,Consolidado!A10,Detalle!$D$2:$D$940,Consolidado!D10) -> -87810.46 | I10: =SUMIFS(Detalle!$I$2:$I$940,Detalle!$A$2:$A$940,Consolidado!A10,Detalle!$D$2:$D$940,Consolidado!D10) -> 3.6326928e+08 | J10: =G10-(E10+H10) -> -164.72 | K10: =1-ABS($G10-(E10+H10))/G10 -> 0.99999955 | L10: =G10-(F10+H10) -> -164.72 | M10: =1-ABS($G10-(F10+H10))/(G10) -> 0.99999955 | N10: =I10-(F10+H10) -> -14.24669 | O10: =1-ABS($I10-(F10+H10))/I10 -> 0.99999996
A11: HPC | B11: Créditos (consumo, vehicular, etc) | C11: - | D11: PSS | E11: =SUMIFS(Detalle!$E$2:$E$940,Detalle!$A$2:$A$940,Consolidado!A11,Detalle!$D$2:$D$940,Consolidado!D11) -> 1.4834743e+10 | F11: =SUMIFS(Detalle!$F$2:$F$940,Detalle!$A$2:$A$940,Consolidado!A11,Detalle!$D$2:$D$940,Consolidado!D11) -> 1.4834743e+10 | G11: =SUMIFS(Detalle!$G$2:$G$940,Detalle!$A$2:$A$940,Consolidado!A11,Detalle!$D$2:$D$940,Consolidado!D11) -> 1.4834993e+10 | H11: =SUMIFS(Detalle!$H$2:$H$940,Detalle!$A$2:$A$940,Consolidado!A11,Detalle!$D$2:$D$940,Consolidado!D11) -> 250000 | I11: =SUMIFS(Detalle!$I$2:$I$940,Detalle!$A$2:$A$940,Consolidado!A11,Detalle!$D$2:$D$940,Consolidado!D11) -> 1.4834993e+10 | J11: =G11-(E11+H11) -> 0 | K11: =1-ABS($G11-(E11+H11))/G11 -> 1 | L11: =G11-(F11+H11) -> 0 | M11: =1-ABS($G11-(F11+H11))/(G11) -> 1 | N11: =I11-(F11+H11) -> 0 | O11: =1-ABS($I11-(F11+H11))/I11 -> 1
A12: HPC | B12: Créditos (consumo, vehicular, etc) | C12: - | D12: USD | E12: =SUMIFS(Detalle!$E$2:$E$940,Detalle!$A$2:$A$940,Consolidado!A12,Detalle!$D$2:$D$940,Consolidado!D12) -> 1.4653492e+08 | F12: =SUMIFS(Detalle!$F$2:$F$940,Detalle!$A$2:$A$940,Consolidado!A12,Detalle!$D$2:$D$940,Consolidado!D12) -> 1.4653492e+08 | G12: =SUMIFS(Detalle!$G$2:$G$940,Detalle!$A$2:$A$940,Consolidado!A12,Detalle!$D$2:$D$940,Consolidado!D12) -> 1.465349e+08 | H12: =SUMIFS(Detalle!$H$2:$H$940,Detalle!$A$2:$A$940,Consolidado!A12,Detalle!$D$2:$D$940,Consolidado!D12) -> 0 | I12: =SUMIFS(Detalle!$I$2:$I$940,Detalle!$A$2:$A$940,Consolidado!A12,Detalle!$D$2:$D$940,Consolidado!D12) -> 1.4653492e+08 | J12: =G12-(E12+H12) -> -18.41 | K12: =1-ABS($G12-(E12+H12))/G12 -> 0.99999987 | L12: =G12-(F12+H12) -> -18.41 | M12: =1-ABS($G12-(F12+H12))/(G12) -> 0.99999987 | N12: =I12-(F12+H12) -> -0.013545513 | O12: =1-ABS($I12-(F12+H12))/I12 -> 1
A13: JCC | B13: Judicial Condonación o Castigo | C13: - | D13: PSS | E13: =SUMIFS(Detalle!$E$2:$E$940,Detalle!$A$2:$A$940,Consolidado!A13,Detalle!$D$2:$D$940,Consolidado!D13) -> 6.0844295e+08 | F13: =SUMIFS(Detalle!$F$2:$F$940,Detalle!$A$2:$A$940,Consolidado!A13,Detalle!$D$2:$D$940,Consolidado!D13) -> 6.0844295e+08 | G13: =SUMIFS(Detalle!$G$2:$G$940,Detalle!$A$2:$A$940,Consolidado!A13,Detalle!$D$2:$D$940,Consolidado!D13) -> 6.0853514e+08 | H13: =SUMIFS(Detalle!$H$2:$H$940,Detalle!$A$2:$A$940,Consolidado!A13,Detalle!$D$2:$D$940,Consolidado!D13) -> 92185.84 | I13: =SUMIFS(Detalle!$I$2:$I$940,Detalle!$A$2:$A$940,Consolidado!A13,Detalle!$D$2:$D$940,Consolidado!D13) -> 6.0853514e+08 | J13: =G13-(E13+H13) -> 0 | K13: =1-ABS($G13-(E13+H13))/G13 -> 1 | L13: =G13-(F13+H13) -> 0 | M13: =1-ABS($G13-(F13+H13))/(G13) -> 1 | N13: =I13-(F13+H13) -> 0 | O13: =1-ABS($I13-(F13+H13))/I13 -> 1
A14: JCC | B14: Judicial Condonación o Castigo | C14: - | D14: USD | E14: =SUMIFS(Detalle!$E$2:$E$940,Detalle!$A$2:$A$940,Consolidado!A14,Detalle!$D$2:$D$940,Consolidado!D14) -> 38611282 | F14: =SUMIFS(Detalle!$F$2:$F$940,Detalle!$A$2:$A$940,Consolidado!A14,Detalle!$D$2:$D$940,Consolidado!D14) -> 38611282 | G14: =SUMIFS(Detalle!$G$2:$G$940,Detalle!$A$2:$A$940,Consolidado!A14,Detalle!$D$2:$D$940,Consolidado!D14) -> 38611276 | H14: =SUMIFS(Detalle!$H$2:$H$940,Detalle!$A$2:$A$940,Consolidado!A14,Detalle!$D$2:$D$940,Consolidado!D14) -> 0 | I14: =SUMIFS(Detalle!$I$2:$I$940,Detalle!$A$2:$A$940,Consolidado!A14,Detalle!$D$2:$D$940,Consolidado!D14) -> 38611200 | J14: =G14-(E14+H14) -> -5.8 | K14: =1-ABS($G14-(E14+H14))/G14 -> 0.99999985 | L14: =G14-(F14+H14) -> -5.8 | M14: =1-ABS($G14-(F14+H14))/(G14) -> 0.99999985 | N14: =I14-(F14+H14) -> -81.903443 | O14: =1-ABS($I14-(F14+H14))/I14 -> 0.99999788
A15: LIC | B15: Créditos consumo por convenio | C15: CASE WHEN P01_ID_APLI IN ('$IC', 'LIC') AND NVL(P01_RUBRO, ' ') <> '01' THEN 1 ELSE 0 END FLGACU_IC_LIC, /*FILTRO 08: Registros de $IC y LIC*/ | D15: PSS | E15: =SUMIFS(Detalle!$E$2:$E$940,Detalle!$A$2:$A$940,Consolidado!A15,Detalle!$D$2:$D$940,Consolidado!D15) -> 5.5248218e+09 | F15: =SUMIFS(Detalle!$F$2:$F$940,Detalle!$A$2:$A$940,Consolidado!A15,Detalle!$D$2:$D$940,Consolidado!D15) -> 5.5248218e+09 | G15: =SUMIFS(Detalle!$G$2:$G$940,Detalle!$A$2:$A$940,Consolidado!A15,Detalle!$D$2:$D$940,Consolidado!D15) -> 5.5248218e+09 | H15: =SUMIFS(Detalle!$H$2:$H$940,Detalle!$A$2:$A$940,Consolidado!A15,Detalle!$D$2:$D$940,Consolidado!D15) -> 0 | I15: =SUMIFS(Detalle!$I$2:$I$940,Detalle!$A$2:$A$940,Consolidado!A15,Detalle!$D$2:$D$940,Consolidado!D15) -> 5.5248218e+09 | J15: =G15-(E15+H15) -> 0 | K15: =1-ABS($G15-(E15+H15))/G15 -> 1 | L15: =G15-(F15+H15) -> 0 | M15: =1-ABS($G15-(F15+H15))/(G15) -> 1 | N15: =I15-(F15+H15) -> 0 | O15: =1-ABS($I15-(F15+H15))/I15 -> 1
A16: LPC | B16: Leasing y pagaré en cuotas | C16: CASE WHEN P01_ID_APLI IN ('LSG', 'LPC') AND NOT ((NVL(P01_CO_PROD, ' ') = '113' OR (NVL(P01_CO_PROD, ' ') = '198' AND NVL(P01_CO_SUB_PROD, ' ') = '113')) AND NVL(P01_RUBRO, ' ') IN ('01', '18')) AND NOT (NVL(P01_RUBRO, ' ') IN ('01', '18', '16')) THEN 1 ELSE 0 END FLGACU_LSG_LPC, /*FILTRO 10: Registros de LSG y LPC*/ | D16: PSS | E16: =SUMIFS(Detalle!$E$2:$E$940,Detalle!$A$2:$A$940,Consolidado!A16,Detalle!$D$2:$D$940,Consolidado!D16) -> 8.6361981e+09 | F16: =SUMIFS(Detalle!$F$2:$F$940,Detalle!$A$2:$A$940,Consolidado!A16,Detalle!$D$2:$D$940,Consolidado!D16) -> 8.6361981e+09 | G16: =SUMIFS(Detalle!$G$2:$G$940,Detalle!$A$2:$A$940,Consolidado!A16,Detalle!$D$2:$D$940,Consolidado!D16) -> 8.6666603e+09 | H16: =SUMIFS(Detalle!$H$2:$H$940,Detalle!$A$2:$A$940,Consolidado!A16,Detalle!$D$2:$D$940,Consolidado!D16) -> -1574922.9 | I16: =SUMIFS(Detalle!$I$2:$I$940,Detalle!$A$2:$A$940,Consolidado!A16,Detalle!$D$2:$D$940,Consolidado!D16) -> 8.6346232e+09 | J16: =G16-(E16+H16) -> 32037081 | K16: =1-ABS($G16-(E16+H16))/G16 -> 0.99630341 | L16: =G16-(F16+H16) -> 32037081 | M16: =1-ABS($G16-(F16+H16))/(G16) -> 0.99630341 | N16: =I16-(F16+H16) -> 0 | O16: =1-ABS($I16-(F16+H16))/I16 -> 1 | P16: 25/06: Falta Sustentar
A17: LPC | B17: Leasing y pagaré en cuotas | C17: CASE WHEN P01_ID_APLI IN ('LSG', 'LPC') AND NOT ((NVL(P01_CO_PROD, ' ') = '113' OR (NVL(P01_CO_PROD, ' ') = '198' AND NVL(P01_CO_SUB_PROD, ' ') = '113')) AND NVL(P01_RUBRO, ' ') IN ('01', '18')) AND NOT (NVL(P01_RUBRO, ' ') IN ('01', '18', '16')) THEN 1 ELSE 0 END FLGACU_LSG_LPC, /*FILTRO 10: Registros de LSG y LPC*/ | D17: USD | E17: =SUMIFS(Detalle!$E$2:$E$940,Detalle!$A$2:$A$940,Consolidado!A17,Detalle!$D$2:$D$940,Consolidado!D17) -> 3.105458e+09 | F17: =SUMIFS(Detalle!$F$2:$F$940,Detalle!$A$2:$A$940,Consolidado!A17,Detalle!$D$2:$D$940,Consolidado!D17) -> 3.105458e+09 | G17: =SUMIFS(Detalle!$G$2:$G$940,Detalle!$A$2:$A$940,Consolidado!A17,Detalle!$D$2:$D$940,Consolidado!D17) -> 3.105477e+09 | H17: =SUMIFS(Detalle!$H$2:$H$940,Detalle!$A$2:$A$940,Consolidado!A17,Detalle!$D$2:$D$940,Consolidado!D17) -> 0 | I17: =SUMIFS(Detalle!$I$2:$I$940,Detalle!$A$2:$A$940,Consolidado!A17,Detalle!$D$2:$D$940,Consolidado!D17) -> 3.105458e+09 | J17: =G17-(E17+H17) -> 18950.53 | K17: =1-ABS($G17-(E17+H17))/G17 -> 0.9999939 | L17: =G17-(F17+H17) -> 18950.53 | M17: =1-ABS($G17-(F17+H17))/(G17) -> 0.9999939 | N17: =I17-(F17+H17) -> 0.0065207481 | O17: =1-ABS($I17-(F17+H17))/I17 -> 1 | P17: 25/06: Falta Sustentar
A18: MDC | B18: Tesorería | C18: - | D18: USD | E18: =SUMIFS(Detalle!$E$2:$E$940,Detalle!$A$2:$A$940,Consolidado!A18,Detalle!$D$2:$D$940,Consolidado!D18) -> 1.2026654e+09 | F18: =SUMIFS(Detalle!$F$2:$F$940,Detalle!$A$2:$A$940,Consolidado!A18,Detalle!$D$2:$D$940,Consolidado!D18) -> 1.0698898e+09 | G18: =SUMIFS(Detalle!$G$2:$G$940,Detalle!$A$2:$A$940,Consolidado!A18,Detalle!$D$2:$D$940,Consolidado!D18) -> 1.2848057e+09 | H18: =SUMIFS(Detalle!$H$2:$H$940,Detalle!$A$2:$A$940,Consolidado!A18,Detalle!$D$2:$D$940,Consolidado!D18) -> 2.1491589e+08 | I18: =SUMIFS(Detalle!$I$2:$I$940,Detalle!$A$2:$A$940,Consolidado!A18,Detalle!$D$2:$D$940,Consolidado!D18) -> 1.4175813e+09 | J18: =G18-(E18+H18) -> -1.3277564e+08 | K18: =1-ABS($G18-(E18+H18))/G18 -> 0.89665703 | L18: =G18-(F18+H18) -> -0.12000012 | M18: =1-ABS($G18-(F18+H18))/(G18) -> 1 | N18: =I18-(F18+H18) -> 1.3277564e+08 | O18: =1-ABS($I18-(F18+H18))/I18 -> 0.9063365 | P18: 25/06: Sustentado
A19: MDC | B19: Tesorería | C19: - | D19: PSS | E19: =SUMIFS(Detalle!$E$2:$E$940,Detalle!$A$2:$A$940,Consolidado!A19,Detalle!$D$2:$D$940,Consolidado!D19) -> 1.5925186e+10 | F19: =SUMIFS(Detalle!$F$2:$F$940,Detalle!$A$2:$A$940,Consolidado!A19,Detalle!$D$2:$D$940,Consolidado!D19) -> 8.283255e+09 | G19: =SUMIFS(Detalle!$G$2:$G$940,Detalle!$A$2:$A$940,Consolidado!A19,Detalle!$D$2:$D$940,Consolidado!D19) -> 8.556839e+09 | H19: =SUMIFS(Detalle!$H$2:$H$940,Detalle!$A$2:$A$940,Consolidado!A19,Detalle!$D$2:$D$940,Consolidado!D19) -> 2.7358395e+08 | I19: =SUMIFS(Detalle!$I$2:$I$940,Detalle!$A$2:$A$940,Consolidado!A19,Detalle!$D$2:$D$940,Consolidado!D19) -> 1.619877e+10 | J19: =G19-(E19+H19) -> -7.6419313e+09 | K19: =1-ABS($G19-(E19+H19))/G19 -> 0.10692123 | L19: =G19-(F19+H19) -> 0 | M19: =1-ABS($G19-(F19+H19))/(G19) -> 1 | N19: =I19-(F19+H19) -> 7.6419313e+09 | O19: =1-ABS($I19-(F19+H19))/I19 -> 0.52824004 | P19: 25/06: Sustentado
A20: MDC | B20: Tesorería | C20: - | D20: PS2 | E20: =SUMIFS(Detalle!$E$2:$E$940,Detalle!$A$2:$A$940,Consolidado!A20,Detalle!$D$2:$D$940,Consolidado!D20) -> 2.5622553e+08 | F20: =SUMIFS(Detalle!$F$2:$F$940,Detalle!$A$2:$A$940,Consolidado!A20,Detalle!$D$2:$D$940,Consolidado!D20) -> 2.5622553e+08 | G20: =SUMIFS(Detalle!$G$2:$G$940,Detalle!$A$2:$A$940,Consolidado!A20,Detalle!$D$2:$D$940,Consolidado!D20) -> 2.5622553e+08 | H20: =SUMIFS(Detalle!$H$2:$H$940,Detalle!$A$2:$A$940,Consolidado!A20,Detalle!$D$2:$D$940,Consolidado!D20) -> 0 | I20: =SUMIFS(Detalle!$I$2:$I$940,Detalle!$A$2:$A$940,Consolidado!A20,Detalle!$D$2:$D$940,Consolidado!D20) -> 2.5622553e+08 | J20: =G20-(E20+H20) -> 0 | K20: =1-ABS($G20-(E20+H20))/G20 -> 1 | L20: =G20-(F20+H20) -> 0 | M20: =1-ABS($G20-(F20+H20))/(G20) -> 1 | N20: =I20-(F20+H20) -> 0 | O20: =1-ABS($I20-(F20+H20))/I20 -> 1
A21: MYP | B21: Micro pequeña empresa | C21: - | D21: PSS | E21: =SUMIFS(Detalle!$E$2:$E$940,Detalle!$A$2:$A$940,Consolidado!A21,Detalle!$D$2:$D$940,Consolidado!D21) -> 1.8293282e+09 | F21: =SUMIFS(Detalle!$F$2:$F$940,Detalle!$A$2:$A$940,Consolidado!A21,Detalle!$D$2:$D$940,Consolidado!D21) -> 1.8293282e+09 | G21: =SUMIFS(Detalle!$G$2:$G$940,Detalle!$A$2:$A$940,Consolidado!A21,Detalle!$D$2:$D$940,Consolidado!D21) -> 1.8293282e+09 | H21: =SUMIFS(Detalle!$H$2:$H$940,Detalle!$A$2:$A$940,Consolidado!A21,Detalle!$D$2:$D$940,Consolidado!D21) -> -5.8207661e-11 | I21: =SUMIFS(Detalle!$I$2:$I$940,Detalle!$A$2:$A$940,Consolidado!A21,Detalle!$D$2:$D$940,Consolidado!D21) -> 1.8293282e+09 | J21: =G21-(E21+H21) -> 0 | K21: =1-ABS($G21-(E21+H21))/G21 -> 1 | L21: =G21-(F21+H21) -> 0 | M21: =1-ABS($G21-(F21+H21))/(G21) -> 1 | N21: =I21-(F21+H21) -> 0 | O21: =1-ABS($I21-(F21+H21))/I21 -> 1
A22: MYP | B22: Micro pequeña empresa | C22: - | D22: USD | E22: =SUMIFS(Detalle!$E$2:$E$940,Detalle!$A$2:$A$940,Consolidado!A22,Detalle!$D$2:$D$940,Consolidado!D22) -> 1677772 | F22: =SUMIFS(Detalle!$F$2:$F$940,Detalle!$A$2:$A$940,Consolidado!A22,Detalle!$D$2:$D$940,Consolidado!D22) -> 1677772 | G22: =SUMIFS(Detalle!$G$2:$G$940,Detalle!$A$2:$A$940,Consolidado!A22,Detalle!$D$2:$D$940,Consolidado!D22) -> 1677771.9 | H22: =SUMIFS(Detalle!$H$2:$H$940,Detalle!$A$2:$A$940,Consolidado!A22,Detalle!$D$2:$D$940,Consolidado!D22) -> 0 | I22: =SUMIFS(Detalle!$I$2:$I$940,Detalle!$A$2:$A$940,Consolidado!A22,Detalle!$D$2:$D$940,Consolidado!D22) -> 1677772 | J22: =G22-(E22+H22) -> -0.12 | K22: =1-ABS($G22-(E22+H22))/G22 -> 0.99999993 | L22: =G22-(F22+H22) -> -0.12 | M22: =1-ABS($G22-(F22+H22))/(G22) -> 0.99999993 | N22: =I22-(F22+H22) -> -0.016823998 | O22: =1-(ABS($I22-(F22+H22))/(F22+H22)) -> 0.99999999
A25: Query con filtros y agrupaciones
A26: SELECT X.AS_OF_DATE, X.CUENTA_CONTABLE, X.MONEDA, X.TIPO_MONEDA, X.COMMON_COA_ID, --APRRMTX_SI_PROD AS CREDIT_STATUS_CD, SUM(CUR_BOOK_BAL) AS CUR_BOOK_BAL FROM ( SELECT A.*, FECHA_PROCESO AS AS_OF_DATE, P01_CT_CONT1_MTR as Cuenta_Contable, P01_CTRL02 as Moneda, case when P01_CTRL02 = 0001 THEN 'PSS' when P01_CTRL02 = 0010 THEN 'USD' when P01_CTRL02 = 0015 THEN 'USD' when P01_CTRL02 = 0035 THEN 'USD' end as Tipo_Moneda, NVL( CASE WHEN SUBSTR(APRRMTX_CO_FAMILIA, -2, 1) = '0' THEN SUBSTR(APRRMTX_CO_FAMILIA, -1) ELSE SUBSTR(APRRMTX_CO_FAMILIA, -2) END ,'') || NVL(SUBSTR(APRRMTX_CO_SUB_FAMILIA, -2), '') || NVL(SUBSTR(APRRMTX_CO_PRODUCTO, -2), '') || NVL(SUBSTR(APRRMTX_CO_SUB_PRODUCTO, -2), '') || NVL(SUBSTR(APRRMTX_CO_COMPONENTE, -2), '') AS COMMON_COA_ID, NULL AS ISO_CURRENCY_CD, NULL AS CREDIT_STATUS_CD, CASE when P01_CTRL02 = 0001 THEN P01_IM_SALD when P01_CTRL02 = 0010 THEN P01_IM_SALD when P01_CTRL02 = 0035 THEN (P01_IM_SALD * 4.778534 / 3.517) when P01_CTRL02 = 0015 THEN (P01_IM_SALD*1.177)--APROXIMADO, NO SE TIENE T.C CONFIRMADO END AS CUR_BOOK_BAL, -- Inicio de Filtros de Fuente --CASE WHEN P01_ID_APLI NOT IN (SELECT APLI_COD3 FROM RNT.T_APLICATIVO WHERE APLI_ESTADO=1) THEN 1 ELSE 0 END FLGPRO_APL, /*FILTRO 01: Aplicativos Fuente*/ CASE WHEN NVL(P01_TIPO_CUENTA, ' ') = 'PRIN' THEN 0 ELSE 1 END FLGPRO_PRI, /*FILTRO 02: Tipo Cuenta Principal*/ CASE WHEN NOT (NVL(P01_RUBRO, ' ') = ' ' AND NVL(P01_ID_CLIE, '9999999999') = '9999999999') THEN 0 ELSE 1 END FLGPRO_CLI, /*FILTRO 03: Cliente y Rubro Nulos*/ CASE WHEN NOT (NVL(P01_ID_APLI, ' ') = 'LPC' AND (NVL(P01_ID_CAMP_07, ' ') IN ('PDL', 'PDS'))) THEN 0 ELSE 1 END FLGPRO_C07, /*FILTRO 04: Campo de llave APR de LPC*/ CASE WHEN NOT NVL(P01_RUBRO, ' ') IN ('14', '50', '51', '52') THEN 0 ELSE 1 END FLGPRO_RUB, /*FILTRO 05: Rubros*/ CASE WHEN NOT NVL(P01_FLAG_T_DESCONTADO, ' ') = 'S' THEN 0 ELSE 1 END FLGPRO_DES, /*FILTRO 06: Campo flag_t_descontado*/ CASE WHEN P01_ID_APLI = '$IM' AND SUBSTR(P01_CT_CONT1_MTR, 1, 6) IN ('810402', '810409') THEN 1 ELSE 0 END FLGACU_IM_CTA, /*FILTRO 07: Cuentas Contables de $IM*/ CASE WHEN P01_ID_APLI IN ('$IC', 'LIC') AND NVL(P01_RUBRO, ' ') <> '01' THEN 1 ELSE 0 END FLGACU_IC_LIC, /*FILTRO 08: Registros de $IC y LIC*/ CASE WHEN P01_ID_APLI IN ('$PR', 'FCD') AND NOT (NVL(P01_RUBRO, ' ') IN ('01', '18') OR NVL(P01_RUBRO, ' ') = '04' AND (NVL(P01_CO_PROD, ' ') IN ('304', '305') OR NVL(P01_CO_PROD, ' ') = '198' AND NVL(P01_CO_SUB_PROD, ' ') IN ('304', '305'))) THEN 1 ELSE 0 END FLGACU_PR_FCD, /*FILTRO 09: Registros de $PR y FCD*/ CASE WHEN P01_ID_APLI IN ('LSG', 'LPC') AND NOT ((NVL(P01_CO_PROD, ' ') = '113' OR (NVL(P01_CO_PROD, ' ') = '198' AND NVL(P01_CO_SUB_PROD, ' ') = '113')) AND NVL(P01_RUBRO, ' ') IN ('01', '18')) AND NOT (NVL(P01_RUBRO, ' ') IN ('01', '18', '16')) THEN 1 ELSE 0 END FLGACU_LSG_LPC, /*FILTRO 10: Registros de LSG y LPC*/ CASE WHEN P01_ID_APLI IN ('$IM', '$ST') AND NOT (NVL(P01_RUBRO, ' ') IN ('01', '03') AND P01_NU_SECU < 2) THEN 1 ELSE 0 END FLGACU_IM_ST, /*FILTRO 11: Registros de $IM y $ST*/ CASE WHEN P01_ID_APLI = 'BKT' AND NOT ((NVL(P01_CO_PROD, ' ') = '301' AND NVL(P01_CO_SUB_PROD, ' ') = '307' AND NVL(P01_RUBRO, ' ') = '04') OR (NVL(P01_CO_PROD, ' ') <> '301' OR NVL(P01_CO_SUB_PROD, ' ') <> '307')) THEN 1 ELSE 0 END FLGACU_BKT, /*FILTRO 12: Registros de BKT*/ CASE WHEN P01_ID_APLI = 'FMU' AND P01_NU_SECU <> 1 THEN 1 ELSE 0 END FLGACU_FMU, /*FILTRO 13: Registros de FMU*/ CASE WHEN APRRMTX_CO_TABL_INSTR IN ('CHEC', 'COMM', 'CONS', 'CRED', 'DEPO', 'INV', 'INVE', 'LEAS', 'MORT', 'OFFB', 'SAVI') THEN 0 ELSE 1 END FLGAOK_TAB, /*FILTRO 14: C digo de Tabla de Instrumento*/ CASE WHEN SUBSTR(NVL(TRIM(P01_CT_CONT1_MTR), '00000000000000'), 1, 4) NOT IN ('8103', '8104') AND SUBSTR(NVL(TRIM(P01_CT_CONT1_MTR), '00000000000000'), 1, 6) NOT IN ('840602', '840919') OR SUBSTR(NVL(TRIM(P01_CT_CONT1_MTR), '00000000000000'), 1, 6) IN ('810302', '810922') THEN 0 ELSE 1 END FLGAOK_CTA_CTB, /*FILTRO 15: Cuentas Contables*/ CASE WHEN APRRMTX_CO_TABL_INSTR IN ('CHEC', 'COMM', 'CONS', 'CRED', 'LEAS', 'MORT', 'OFFB') AND DWHRR_TI_REGI IN ('CAS', 'CON') THEN 1 ELSE 0 END FLGT01_CAS_CON /*FILTRO 16: Documentos castigados y condonados*/ FROM RNT.T_APRRINT_HIST_20260430 A )X WHERE --FLGPRO_APL= 0 AND FLGPRO_PRI = 0 AND FLGPRO_CLI = 0 AND FLGPRO_C07 = 0 AND FLGPRO_RUB = 0 AND FLGPRO_DES = 0 AND FLGACU_IM_CTA = 0 AND FLGACU_IC_LIC = 0 AND FLGACU_PR_FCD = 0 AND FLGACU_LSG_LPC = 0 AND FLGACU_IM_ST = 0 AND FLGACU_BKT = 0 AND FLGACU_FMU = 0 AND FLGAOK_TAB = 0 AND FLGAOK_CTA_CTB = 0 AND FLGT01_CAS_CON = 0 GROUP BY X.AS_OF_DATE, X.CUENTA_CONTABLE, X.MONEDA, X.TIPO_MONEDA, X.COMMON_COA_ID;

Sheet Detalle
A1: Aplicativo | B1: Producto | C1: Cuenta Contable | D1: Moneda | E1: Saldo Aplicativo sin Filtro | F1: Saldo Aplicativo con Filtro y agrupaciones | G1: Saldos Finanzas | H1: Ajuste RCD | I1: Saldos Contables | J1: Diff Sal.Fin vs (Sal.Apr S.F + Ajus.RCD) | K1: Diff Sal.Fin vs (Sal.Apr C.F + Ajus.RCD) | L1: Diff Sal.Cont vs (Sal.Apr S.F + Ajus.RCD) | M1: Diff Sal.Cont vs (Sal.Apr C.F + Ajus.RCD) | N1: Saldos de reclasificación a otra cuenta contable | O1: Diferencia | P1: Detalle cuenta contable | Q1: Comentario
A2: $IM | B2: Cuentas Corrientes | C2: 14010204000106 | D2: PSS | E2: 473.82 | F2: 473.82 | G2: 473.82 | I2: 473.82 | J2: =G2-E2 -> 0 | K2: =G2-F2 -> 0 | L2: =I2-E2 -> 0 | M2: =I2-F2 -> 0 | P2: =VLOOKUP(C2,[1]plan_cc!$B$1:$C$65536,2,0) -> SOBREGIRO CTAS CTE S/F PJ MES106
A3: $IM | B3: Cuentas Corrientes | C3: 14010204000106 | D3: USD | E3: 160.72 | F3: 160.72 | G3: 160.69 | I3: 160.74211 | J3: =G3-E3 -> -0.03 | K3: =G3-F3 -> -0.03 | L3: =I3-E3 -> 0.022109753 | M3: =I3-F3 -> 0.022109753 | P3: =VLOOKUP(C3,[1]plan_cc!$B$1:$C$65536,2,0) -> SOBREGIRO CTAS CTE S/F PJ MES106
A4: $IM | B4: Cuentas Corrientes | C4: 14010301000101 | D4: PSS | E4: 4528.6 | F4: 4528.6 | G4: 4528.6 | I4: 4528.6 | J4: =G4-E4 -> 0 | K4: =G4-F4 -> 0 | L4: =I4-E4 -> 0 | M4: =I4-F4 -> 0 | P4: =VLOOKUP(C4,[1]plan_cc!$B$1:$C$65536,2,0) -> AVANCES EN CTA CTE CONTRATADOS PN
A5: $IM | B5: Cuentas Corrientes | C5: 14010704000102 | D5: USD | E5: 0 | F5: 0 | G5: 0 | I5: 0 | J5: =G5-E5 -> 0 | K5: =G5-F5 -> 0 | L5: =I5-E5 -> 0 | M5: =I5-F5 -> 0 | P5: =VLOOKUP(C5,[1]plan_cc!$B$1:$C$65536,2,0) -> IM SOBREGIRO CTA CTE PJ S/F CESP
A6: $IM | B6: Cuentas Corrientes | C6: 14010801000102 | D6: PSS | E6: 0 | F6: 0 | G6: 0 | I6: 0 | J6: =G6-E6 -> 0 | K6: =G6-F6 -> 0 | L6: =I6-E6 -> 0 | M6: =I6-F6 -> 0 | P6: =VLOOKUP(C6,[1]plan_cc!$B$1:$C$65536,2,0) -> IM AVANCE CTA CTE PJ S/F CIVA
A7: $IM | B7: Cuentas Corrientes | C7: 14010804000102 | D7: PSS | E7: 0 | F7: 0 | G7: 0 | I7: 0 | J7: =G7-E7 -> 0 | K7: =G7-F7 -> 0 | L7: =I7-E7 -> 0 | M7: =I7-F7 -> 0 | P7: =VLOOKUP(C7,[1]plan_cc!$B$1:$C$65536,2,0) -> IM SOBREGIRO CTA CTE PJ S/F CIVA
A8: $IM | B8: Cuentas Corrientes | C8: 14010804000102 | D8: USD | E8: 271.23 | F8: 271.23 | G8: 271.22 | I8: 271.22548 | J8: =G8-E8 -> -0.01 | K8: =G8-F8 -> -0.01 | L8: =I8-E8 -> -0.0045237418 | M8: =I8-F8 -> -0.0045237418 | P8: =VLOOKUP(C8,[1]plan_cc!$B$1:$C$65536,2,0) -> IM SOBREGIRO CTA CTE PJ S/F CIVA
A9: $IM | B9: Cuentas Corrientes | C9: 14010999010301 | D9: PSS | G9: 65.34 | H9: 65.34 | I9: 65.34 | J9: =H9-G9 -> 0 | K9: =G9-H9 -> 0 | L9: 0 | M9: 0 | P9: =VLOOKUP(C9,[1]plan_cc!$B$1:$C$65536,2,0) -> BANCO DE CREDITO DEL PERU CESF
A10: $IM | B10: Cuentas Corrientes | C10: 14010999010901 | D10: PSS | E10: 65.34 | F10: 65.34 | G10: 0 | H10: -65.34 | I10: 0 | J10: =G10-(E10+H10) -> 0 | K10: =G10-(F10+H10) -> 0 | L10: =I10-(H10+E10) -> 0 | M10: =I10-(F10+H10) -> 0 | P10: =VLOOKUP(C10,[1]plan_cc!$B$1:$C$65536,2,0) -> BANCO FINANCIERO DEL PERU
A11: $IM | B11: Cuentas Corrientes | C11: 14010999012102 | D11: USD | E11: 0 | F11: 0 | G11: 0 | I11: 0 | J11: =G11-E11 -> 0 | K11: =G11-F11 -> 0 | L11: =I11-E11 -> 0 | M11: =I11-F11 -> 0 | P11: =VLOOKUP(C11,[1]plan_cc!$B$1:$C$65536,2,0) -> BANCO INTERAMERICANO DE FINANZAS
A12: $IM | B12: Cuentas Corrientes | C12: 14011001000102 | D12: PSS | E12: 74443818 | F12: 74443818 | G12: 74443818 | I12: 74443818 | J12: =G12-E12 -> 0 | K12: =G12-F12 -> 0 | L12: =I12-E12 -> 0 | M12: =I12-F12 -> 0 | P12: =VLOOKUP(C12,[1]plan_cc!$B$1:$C$65536,2,0) -> IM AVANCE CTA CTE PJ S/F CCOR
A13: $IM | B13: Cuentas Corrientes | C13: 14011004000102 | D13: PSS | E13: 537360.52 | F13: 537360.52 | G13: 537360.52 | I13: 537360.52 | J13: =G13-E13 -> 0 | K13: =G13-F13 -> 0 | L13: =I13-E13 -> 0 | M13: =I13-F13 -> 0 | P13: =VLOOKUP(C13,[1]plan_cc!$B$1:$C$65536,2,0) -> IM SOBREGIRO CTA CTE PJ S/F CCOR
A14: $IM | B14: Cuentas Corrientes | C14: 14011004000102 | D14: USD | E14: 1607.62 | F14: 1607.62 | G14: 1607.6 | I14: 1607.6287 | J14: =G14-E14 -> -0.02 | K14: =G14-F14 -> -0.02 | L14: =I14-E14 -> 0.0086607904 | M14: =I14-F14 -> 0.0086607904 | P14: =VLOOKUP(C14,[1]plan_cc!$B$1:$C$65536,2,0) -> IM SOBREGIRO CTA CTE PJ S/F CCOR
A15: $IM | B15: Cuentas Corrientes | C15: 14011004000103 | D15: PSS | E15: 0 | F15: 0 | G15: 0 | I15: 0 | J15: =G15-E15 -> 0 | K15: =G15-F15 -> 0 | L15: =I15-E15 -> 0 | M15: =I15-F15 -> 0 | P15: =VLOOKUP(C15,[1]plan_cc!$B$1:$C$65536,2,0) -> IM SOBRG CTA CTE S/F PJ CCOR
A16: $IM | B16: Cuentas Corrientes | C16: 14011101000102 | D16: PSS | E16: 509822.81 | F16: 509822.81 | G16: 509822.81 | I16: 509822.81 | J16: =G16-E16 -> 0 | K16: =G16-F16 -> 0 | L16: =I16-E16 -> 0 | M16: =I16-F16 -> 0 | P16: =VLOOKUP(C16,[1]plan_cc!$B$1:$C$65536,2,0) -> IM AVANCE CTA CTE PJ S/F CGEM
A17: $IM | B17: Cuentas Corrientes | C17: 14011101000102 | D17: USD | E17: 0 | F17: 0 | G17: 0 | I17: 0 | J17: =G17-E17 -> 0 | K17: =G17-F17 -> 0 | L17: =I17-E17 -> 0 | M17: =I17-F17 -> 0 | P17: =VLOOKUP(C17,[1]plan_cc!$B$1:$C$65536,2,0) -> IM AVANCE CTA CTE PJ S/F CGEM
A18: $IM | B18: Cuentas Corrientes | C18: 14011104000102 | D18: PSS | E18: 6266.48 | F18: 6266.48 | G18: 6266.48 | I18: 6266.48 | J18: =G18-E18 -> 0 | K18: =G18-F18 -> 0 | L18: =I18-E18 -> 0 | M18: =I18-F18 -> 0 | P18: =VLOOKUP(C18,[1]plan_cc!$B$1:$C$65536,2,0) -> IM SOBREGIRO CTA CTE PJ S/F CGEM
A19: $IM | B19: Cuentas Corrientes | C19: 14011104000102 | D19: USD | E19: 9350.55 | F19: 9350.55 | G19: 9350.42 | I19: 9350.5488 | J19: =G19-E19 -> -0.13 | K19: =G19-F19 -> -0.13 | L19: =I19-E19 -> -0.0012368496 | M19: =I19-F19 -> -0.0012368496 | P19: =VLOOKUP(C19,[1]plan_cc!$B$1:$C$65536,2,0) -> IM SOBREGIRO CTA CTE PJ S/F CGEM
A20: $IM | B20: Cuentas Corrientes | C20: 14011104000103 | D20: PSS | G20: 0 | I20: 0 | J20: 0 | K20: 0 | L20: 0 | M20: 0 | P20: =VLOOKUP(C20,[1]plan_cc!$B$1:$C$65536,2,0) -> IM SOBRG CTA CTE S/F PJ CGEM
A21: $IM | B21: Cuentas Corrientes | C21: 14011204000102 | D21: PSS | E21: 25688.39 | F21: 25688.39 | G21: 25688.39 | I21: 25688.39 | J21: =G21-E21 -> 0 | K21: =G21-F21 -> 0 | L21: =I21-E21 -> 0 | M21: =I21-F21 -> 0 | P21: =VLOOKUP(C21,[1]plan_cc!$B$1:$C$65536,2,0) -> IM SOBREGIRO CTA CTE PJ S/F CMED
A22: $IM | B22: Cuentas Corrientes | C22: 14011204000102 | D22: USD | E22: 1745.19 | F22: 1745.19 | G22: 1745.08 | I22: 1745.2175 | J22: =G22-E22 -> -0.11 | K22: =G22-F22 -> -0.11 | L22: =I22-E22 -> 0.027514927 | M22: =I22-F22 -> 0.027514927 | P22: =VLOOKUP(C22,[1]plan_cc!$B$1:$C$65536,2,0) -> IM SOBREGIRO CTA CTE PJ S/F CMED
A23: $IM | B23: Cuentas Corrientes | C23: 14011304000102 | D23: PSS | E23: 2367.14 | F23: 2367.14 | G23: 2367.14 | I23: 2367.14 | J23: =G23-E23 -> 0 | K23: =G23-F23 -> 0 | L23: =I23-E23 -> 0 | M23: =I23-F23 -> 0 | P23: =VLOOKUP(C23,[1]plan_cc!$B$1:$C$65536,2,0) -> IM SOBREGIRO CTA CTE PJ S/F CPEM
A24: $IM | B24: Cuentas Corrientes | C24: 14011304000102 | D24: USD | E24: 117.92 | F24: 117.92 | G24: 117.91 | I24: 117.92721 | J24: =G24-E24 -> -0.01 | K24: =G24-F24 -> -0.01 | L24: =I24-E24 -> 0.0072106909 | M24: =I24-F24 -> 0.0072106909 | P24: =VLOOKUP(C24,[1]plan_cc!$B$1:$C$65536,2,0) -> IM SOBREGIRO CTA CTE PJ S/F CPEM
A25: $IM | B25: Cuentas Corrientes | C25: 14050204000101 | D25: PSS | E25: 100410.84 | F25: 100410.84 | G25: 100410.84 | I25: 100410.84 | J25: =G25-E25 -> 0 | K25: =G25-F25 -> 0 | L25: =I25-E25 -> 0 | M25: =I25-F25 -> 0 | P25: =VLOOKUP(C25,[1]plan_cc!$B$1:$C$65536,2,0) -> SOBREGIRO VENC MES SIN FINES
A26: $IM | B26: Cuentas Corrientes | C26: 14050204000101 | D26: USD | E26: 10398.35 | F26: 10398.35 | G26: 10398.2 | I26: 10024.313 | J26: =G26-E26 -> -0.15 | K26: =G26-F26 -> -0.15 | L26: =I26-E26 -> -374.03666 | M26: =I26-F26 -> -374.03666 | P26: =VLOOKUP(C26,[1]plan_cc!$B$1:$C$65536,2,0) -> SOBREGIRO VENC MES SIN FINES
A27: $IM | B27: Cuentas Corrientes | C27: 14050304000101 | D27: PSS | E27: 321657.3 | F27: 321657.3 | G27: 321657.3 | I27: 321656.3 | J27: =G27-E27 -> 0 | K27: =G27-F27 -> 0 | L27: =I27-E27 -> -1 | M27: =I27-F27 -> -1 | P27: =VLOOKUP(C27,[1]plan_cc!$B$1:$C$65536,2,0) -> SOBREGIROS EN CTA CTE PN
A28: $IM | B28: Cuentas Corrientes | C28: 14050304000101 | D28: USD | E28: 3.76 | F28: 3.76 | G28: 3.75 | I28: 0 | J28: =G28-E28 -> -0.01 | K28: =G28-F28 -> -0.01 | L28: =I28-E28 -> -3.76 | M28: =I28-F28 -> -3.76 | P28: =VLOOKUP(C28,[1]plan_cc!$B$1:$C$65536,2,0) -> SOBREGIROS EN CTA CTE PN
A29: $IM | B29: Cuentas Corrientes | C29: 14051004000202 | D29: PSS | G29: 0 | I29: 0 | J29: 0 | K29: 0 | L29: 0 | M29: 0 | P29: =VLOOKUP(C29,[1]plan_cc!$B$1:$C$65536,2,0) -> IM SOBREG VENC CTA CTE PJ S/F CCOR
A30: $IM | B30: Cuentas Corrientes | C30: 14051004000202 | D30: USD | E30: 683.07 | F30: 683.07 | G30: 683.06 | I30: 683.06796 | J30: =G30-E30 -> -0.01 | K30: =G30-F30 -> -0.01 | L30: =I30-E30 -> -0.002044356 | M30: =I30-F30 -> -0.002044356 | P30: =VLOOKUP(C30,[1]plan_cc!$B$1:$C$65536,2,0) -> IM SOBREG VENC CTA CTE PJ S/F CCOR
A31: $IM | B31: Cuentas Corrientes | C31: 14051104000202 | D31: PSS | E31: 16931631 | F31: 16931631 | G31: 16931631 | I31: 16931631 | J31: =G31-E31 -> 0 | K31: =G31-F31 -> 0 | L31: =I31-E31 -> 0 | M31: =I31-F31 -> 0 | P31: =VLOOKUP(C31,[1]plan_cc!$B$1:$C$65536,2,0) -> IM SOBREG VENC CTA CTE PJ S/F CGEM
A32: $IM | B32: Cuentas Corrientes | C32: 14051104000202 | D32: USD | E32: 43925.86 | F32: 43925.86 | G32: 43925.77 | I32: 43925.852 | J32: =G32-E32 -> -0.09 | K32: =G32-F32 -> -0.09 | L32: =I32-E32 -> -0.0084219505 | M32: =I32-F32 -> -0.0084219505 | P32: =VLOOKUP(C32,[1]plan_cc!$B$1:$C$65536,2,0) -> IM SOBREG VENC CTA CTE PJ S/F CGEM
A33: $IM | B33: Cuentas Corrientes | C33: 14051204000202 | D33: PSS | E33: 2090039.7 | F33: 2090039.7 | G33: 2090039.7 | I33: 2090039.7 | J33: =G33-E33 -> 0 | K33: =G33-F33 -> 0 | L33: =I33-E33 -> 0 | M33: =I33-F33 -> 0 | P33: =VLOOKUP(C33,[1]plan_cc!$B$1:$C$65536,2,0) -> IM SOBREG VENC CTA CTE PJ S/F CMED
A34: $IM | B34: Cuentas Corrientes | C34: 14051204000202 | D34: USD | E34: 406018.82 | F34: 406018.82 | G34: 406018.69 | I34: 406018.84 | J34: =G34-E34 -> -0.13 | K34: =G34-F34 -> -0.13 | L34: =I34-E34 -> 0.022763719 | M34: =I34-F34 -> 0.022763719 | P34: =VLOOKUP(C34,[1]plan_cc!$B$1:$C$65536,2,0) -> IM SOBREG VENC CTA CTE PJ S/F CMED
A35: $IM | B35: Cuentas Corrientes | C35: 14051304000202 | D35: PSS | E35: 723332.67 | F35: 723332.67 | G35: 723332.67 | I35: 723332.67 | J35: =G35-E35 -> 0 | K35: =G35-F35 -> 0 | L35: =I35-E35 -> 0 | M35: =I35-F35 -> 0 | P35: =VLOOKUP(C35,[1]plan_cc!$B$1:$C$65536,2,0) -> IM SOBREG VENC CTA CTE PJ S/F CPEM
A36: $IM | B36: Cuentas Corrientes | C36: 14051304000202 | D36: USD | E36: 78870.93 | F36: 78870.93 | G36: 78870.86 | I36: 78870.918 | J36: =G36-E36 -> -0.07 | K36: =G36-F36 -> -0.07 | L36: =I36-E36 -> -0.011603639 | M36: =I36-F36 -> -0.011603639 | P36: =VLOOKUP(C36,[1]plan_cc!$B$1:$C$65536,2,0) -> IM SOBREG VENC CTA CTE PJ S/F CPEM
A37: $IM | B37: Cuentas Corrientes | C37: 21010109000101 | D37: PSS | E37: 18815298 | F37: 18815298 | G37: 18764664 | I37: 18815298 | J37: =G37-E37 -> -50634.4 | K37: =G37-F37 -> -50634.4 | L37: =I37-E37 -> 0 | M37: =I37-F37 -> 0 | P37: =VLOOKUP(C37,[1]plan_cc!$B$1:$C$65536,2,0) -> DEPOSITOS CTA CTE PN
A38: $IM | B38: Cuentas Corrientes | C38: 21010109000101 | D38: USD | E38: 7983179.1 | F38: 7983179.1 | G38: 7986775.2 | I38: 7983179.1 | J38: =G38-E38 -> 3596.05 | K38: =G38-F38 -> 3596.05 | L38: =I38-E38 -> -0.027119704 | M38: =I38-F38 -> -0.027119704 | P38: =VLOOKUP(C38,[1]plan_cc!$B$1:$C$65536,2,0) -> DEPOSITOS CTA CTE PN
A39: $IM | B39: Cuentas Corrientes | C39: 21010109000102 | D39: PSS | E39: 1281710405 | F39: 1281710405 | G39: 1281710405 | I39: 1.2805744e+09 | J39: =G39-E39 -> 0 | K39: =G39-F39 -> 0 | L39: =I39-E39 -> -1135993.9 | M39: =I39-F39 -> -1135993.9 | P39: =VLOOKUP(C39,[1]plan_cc!$B$1:$C$65536,2,0) -> DEPOSITOS CTA CTE PJ S/F LUCRO
A40: $IM | B40: Cuentas Corrientes | C40: 21010109000102 | D40: USD | E40: 32687134 | F40: 32687134 | G40: 32687132 | I40: 32624397 | J40: =G40-E40 -> -2.61 | K40: =G40-F40 -> -2.61 | L40: =I40-E40 -> -62737.7 | M40: =I40-F40 -> -62737.7 | P40: =VLOOKUP(C40,[1]plan_cc!$B$1:$C$65536,2,0) -> DEPOSITOS CTA CTE PJ S/F LUCRO
...

Sheet Saldos_Finanzas
A1: APP | B1: APP DETALLE | C1: CTA_CTB | D1: MONEDA | E1: CONCATENADO | F1: Suma de SUM(SALDO_ACTUAL) | G1: SALD_APR_SIN_FIILTR | H1: SALD_APR_CON_FILT | I1: SALDO_CONTA | J1: AJUSTE_RCD
A2: $IM | B2: =VLOOKUP(C2,[2]FEM_PARTIES_INSTR!C:D,2,0) -> #N/A | C2: 14010204000106 | D2: PSS | E2: =_xlfn.CONCAT(C2,D2) -> 14010204000106PSS | F2: 473.82 | G2: =IFERROR(VLOOKUP(E2,Apr_sin_filtro!$L$1:$M$882,2,0),"") -> 473.82 | H2: =IFERROR(VLOOKUP(E2,Apr_con_filtro!$D$1:$E$970,2,0),"") -> 473.82 | I2: =IFERROR(VLOOKUP(E2,'Saldos Contables'!C:D,2,0),"") -> 473.82 | J2: =IFERROR(VLOOKUP(E2,Ajuste_RCD!C:D,2,0),"")
A3: $IM | B3: =VLOOKUP(C3,[2]FEM_PARTIES_INSTR!C:D,2,0) -> #N/A | C3: 14010204000106 | D3: USD | E3: =_xlfn.CONCAT(C3,D3) -> 14010204000106USD | F3: 160.69 | G3: =IFERROR(VLOOKUP(E3,Apr_sin_filtro!$L$1:$M$882,2,0),"") -> 160.72 | H3: =IFERROR(VLOOKUP(E3,Apr_con_filtro!$D$1:$E$970,2,0),"") -> 160.72 | I3: =IFERROR(VLOOKUP(E3,'Saldos Contables'!C:D,2,0),"") -> 160.74211 | J3: =IFERROR(VLOOKUP(E3,Ajuste_RCD!C:D,2,0),"")
A4: $IM | B4: =VLOOKUP(C4,[2]FEM_PARTIES_INSTR!C:D,2,0) -> #N/A | C4: 14010301000101 | D4: PSS | E4: =_xlfn.CONCAT(C4,D4) -> 14010301000101PSS | F4: 4528.6 | G4: =IFERROR(VLOOKUP(E4,Apr_sin_filtro!$L$1:$M$882,2,0),"") -> 4528.6 | H4: =IFERROR(VLOOKUP(E4,Apr_con_filtro!$D$1:$E$970,2,0),"") -> 4528.6 | I4: =IFERROR(VLOOKUP(E4,'Saldos Contables'!C:D,2,0),"") -> 4528.6 | J4: =IFERROR(VLOOKUP(E4,Ajuste_RCD!C:D,2,0),"")
A5: $IM | B5: =VLOOKUP(C5,[2]FEM_PARTIES_INSTR!C:D,2,0) -> #N/A | C5: 14010704000102 | D5: USD | E5: =_xlfn.CONCAT(C5,D5) -> 14010704000102USD | F5: 0 | G5: =IFERROR(VLOOKUP(E5,Apr_sin_filtro!$L$1:$M$882,2,0),"") -> 0 | H5: =IFERROR(VLOOKUP(E5,Apr_con_filtro!$D$1:$E$970,2,0),"") -> 0 | I5: =IFERROR(VLOOKUP(E5,'Saldos Contables'!C:D,2,0),"") -> 0 | J5: =IFERROR(VLOOKUP(E5,Ajuste_RCD!C:D,2,0),"")
A6: $IM | B6: =VLOOKUP(C6,[2]FEM_PARTIES_INSTR!C:D,2,0) -> #N/A | C6: 14010801000102 | D6: PSS | E6: =_xlfn.CONCAT(C6,D6) -> 14010801000102PSS | F6: 0 | G6: =IFERROR(VLOOKUP(E6,Apr_sin_filtro!$L$1:$M$882,2,0),"") -> 0 | H6: =IFERROR(VLOOKUP(E6,Apr_con_filtro!$D$1:$E$970,2,0),"") -> 0 | I6: =IFERROR(VLOOKUP(E6,'Saldos Contables'!C:D,2,0),"") -> 0 | J6: =IFERROR(VLOOKUP(E6,Ajuste_RCD!C:D,2,0),"")
A7: $IM | B7: =VLOOKUP(C7,[2]FEM_PARTIES_INSTR!C:D,2,0) -> #N/A | C7: 14010804000102 | D7: PSS | E7: =_xlfn.CONCAT(C7,D7) -> 14010804000102PSS | F7: 0 | G7: =IFERROR(VLOOKUP(E7,Apr_sin_filtro!$L$1:$M$882,2,0),"") -> 0 | H7: =IFERROR(VLOOKUP(E7,Apr_con_filtro!$D$1:$E$970,2,0),"") -> 0 | I7: =IFERROR(VLOOKUP(E7,'Saldos Contables'!C:D,2,0),"") -> 0 | J7: =IFERROR(VLOOKUP(E7,Ajuste_RCD!C:D,2,0),"")
A8: $IM | B8: =VLOOKUP(C8,[2]FEM_PARTIES_INSTR!C:D,2,0) -> #N/A | C8: 14010804000102 | D8: USD | E8: =_xlfn.CONCAT(C8,D8) -> 14010804000102USD | F8: 271.22 | G8: =IFERROR(VLOOKUP(E8,Apr_sin_filtro!$L$1:$M$882,2,0),"") -> 271.23 | H8: =IFERROR(VLOOKUP(E8,Apr_con_filtro!$D$1:$E$970,2,0),"") -> 271.23 | I8: =IFERROR(VLOOKUP(E8,'Saldos Contables'!C:D,2,0),"") -> 271.22548 | J8: =IFERROR(VLOOKUP(E8,Ajuste_RCD!C:D,2,0),"")
A9: $IM | B9: =VLOOKUP(C9,[2]FEM_PARTIES_INSTR!C:D,2,0) -> #N/A | C9: 14010999010301 | D9: PSS | E9: =_xlfn.CONCAT(C9,D9) -> 14010999010301PSS | F9: 65.34 | G9: =IFERROR(VLOOKUP(E9,Apr_sin_filtro!$L$1:$M$882,2,0),"") | H9: =IFERROR(VLOOKUP(E9,Apr_con_filtro!$D$1:$E$970,2,0),"") | I9: =IFERROR(VLOOKUP(E9,'Saldos Contables'!C:D,2,0),"") -> 65.34 | J9: =IFERROR(VLOOKUP(E9,Ajuste_RCD!C:D,2,0),"") -> 65.34
A10: $IM | B10: =VLOOKUP(C10,[2]FEM_PARTIES_INSTR!C:D,2,0) -> #N/A | C10: 14010999010901 | D10: PSS | E10: =_xlfn.CONCAT(C10,D10) -> 14010999010901PSS | F10: 0 | G10: =IFERROR(VLOOKUP(E10,Apr_sin_filtro!$L$1:$M$882,2,0),"") -> 65.34 | H10: =IFERROR(VLOOKUP(E10,Apr_con_filtro!$D$1:$E$970,2,0),"") -> 65.34 | I10: =IFERROR(VLOOKUP(E10,'Saldos Contables'!C:D,2,0),"") -> 0 | J10: =IFERROR(VLOOKUP(E10,Ajuste_RCD!C:D,2,0),"") -> -65.34
A11: $IM | B11: =VLOOKUP(C11,[2]FEM_PARTIES_INSTR!C:D,2,0) -> #N/A | C11: 14010999012102 | D11: USD | E11: =_xlfn.CONCAT(C11,D11) -> 14010999012102USD | F11: 0 | G11: =IFERROR(VLOOKUP(E11,Apr_sin_filtro!$L$1:$M$882,2,0),"") -> 0 | H11: =IFERROR(VLOOKUP(E11,Apr_con_filtro!$D$1:$E$970,2,0),"") -> 0 | I11: =IFERROR(VLOOKUP(E11,'Saldos Contables'!C:D,2,0),"") -> 0 | J11: =IFERROR(VLOOKUP(E11,Ajuste_RCD!C:D,2,0),"")
A12: $IM | B12: =VLOOKUP(C12,[2]FEM_PARTIES_INSTR!C:D,2,0) -> #N/A | C12: 14011001000102 | D12: PSS | E12: =_xlfn.CONCAT(C12,D12) -> 14011001000102PSS | F12: 74443818 | G12: =IFERROR(VLOOKUP(E12,Apr_sin_filtro!$L$1:$M$882,2,0),"") -> 74443818 | H12: =IFERROR(VLOOKUP(E12,Apr_con_filtro!$D$1:$E$970,2,0),"") -> 74443818 | I12: =IFERROR(VLOOKUP(E12,'Saldos Contables'!C:D,2,0),"") -> 74443818 | J12: =IFERROR(VLOOKUP(E12,Ajuste_RCD!C:D,2,0),"")
A13: $IM | B13: =VLOOKUP(C13,[2]FEM_PARTIES_INSTR!C:D,2,0) -> #N/A | C13: 14011004000102 | D13: PSS | E13: =_xlfn.CONCAT(C13,D13) -> 14011004000102PSS | F13: 537360.52 | G13: =IFERROR(VLOOKUP(E13,Apr_sin_filtro!$L$1:$M$882,2,0),"") -> 537360.52 | H13: =IFERROR(VLOOKUP(E13,Apr_con_filtro!$D$1:$E$970,2,0),"") -> 537360.52 | I13: =IFERROR(VLOOKUP(E13,'Saldos Contables'!C:D,2,0),"") -> 537360.52 | J13: =IFERROR(VLOOKUP(E13,Ajuste_RCD!C:D,2,0),"")
... A940: MYP | B940: =VLOOKUP(C940,[2]FEM_PARTIES_INSTR!C:D,2,0) -> #N/A | C940: 14051319060101 | D940: PSS | E940: =_xlfn.CONCAT(C940,D940) -> 14051319060101PSS | F940: 1285104.6 | G940: =IFERROR(VLOOKUP(E940,Apr_sin_filtro!$L$1:$M$882,2,0),"") -> 1285104.6 | H940: =IFERROR(VLOOKUP(E940,Apr_con_filtro!$D$1:$E$970,2,0),"") -> 1285104.6 | I940: =IFERROR(VLOOKUP(E940,'Saldos Contables'!C:D,2,0),"") -> 1285104.6 | J940: =IFERROR(VLOOKUP(E940,Ajuste_RCD!C:D,2,0),"")

Sheet Saldos Contables
A1: Cuenta Contable | B1: Moneda | C1: CC + MONEDA | D1: Saldo_contable_soles
A2: 15071900000922 | B2: PSS | C2: 15071900000922PSS | D2: 1788569.2
A3: 25041900000157 | B3: PSS | C3: 25041900000157PSS | D3: 5442404.5
A4: 21070201000403 | B4: PSS | C4: 21070201000403PSS | D4: 3000
A5: 11010101000104 | B5: PSS | C5: 11010101000104PSS | D5: 0
A6: 21070202000203 | B6: PSS | C6: 21070202000203PSS | D6: 8900
A7: 21080301000307 | B7: PSS | C7: 21080301000307PSS | D7: 51671668
A8: 11010200000103 | B8: PSS | C8: 11010200000103PSS | D8: 0
A9: 11010900000101 | B9: PSS | C9: 11010900000101PSS | D9: 0
A10: 21080301000209 | B10: PSS | C10: 21080301000209PSS | D10: 3959.98
A11: 21080701000610 | B11: PSS | C11: 21080701000610PSS | D11: 353712.23
A12: 21080301000308 | B12: PSS | C12: 21080301000308PSS | D12: 1991.1
A13: 11010900000110 | B13: PSS | C13: 11010900000110PSS | D13: 0
... A7613: 38020600000101 | B7613: PSS | C7613: 38020600000101PSS | D7613: 0
A7614: 11010100000101 | B7614: USD | C7614: =_xlfn.CONCAT(A7614,B7614) -> 11010100000101USD | D7614: 91308157
A7615: 11010101000102 | B7615: USD | C7615: =_xlfn.CONCAT(A7615,B7615) -> 11010101000102USD | D7615: 29389682
A7616: 11010101000103 | B7616: USD | C7616: =_xlfn.CONCAT(A7616,B7616) -> 11010101000103USD | D7616: 64911097
A7617: 11010101000104 | B7617: USD | C7617: =_xlfn.CONCAT(A7617,B7617) -> 11010101000104USD | D7617: 869247.37
A7618: 11010200000101 | B7618: USD | C7618: =_xlfn.CONCAT(A7618,B7618) -> 11010200000101USD | D7618: 37531279
A7619: 11010200000102 | B7619: USD | C7619: =_xlfn.CONCAT(A7619,B7619) -> 11010200000102USD | D7619: 22550126
A7620: 11010200000103 | B7620: USD | C7620: =_xlfn.CONCAT(A7620,B7620) -> 11010200000103USD | D7620: 0
A7621: 11010900000101 | B7621: USD | C7621: =_xlfn.CONCAT(A7621,B7621) -> 11010900000101USD | D7621: 901751.98
A7622: 11010900000102 | B7622: USD | C7622: =_xlfn.CONCAT(A7622,B7622) -> 11010900000102USD | D7622: 74150
A7623: 11010900000108 | B7623: USD | C7623: =_xlfn.CONCAT(A7623,B7623) -> 11010900000108USD | D7623: 1407499
A7624: 11010900000109 | B7624: USD | C7624: =_xlfn.CONCAT(A7624,B7624) -> 11010900000109USD | D7624: 1360464
A7625: 11010900000110 | B7625: USD | C7625: =_xlfn.CONCAT(A7625,B7625) -> 11010900000110USD | D7625: 0
... A15225: 39010100000801 | B15225: USD | C15225: =_xlfn.CONCAT(A15225,B15225) -> 39010100000801USD | D15225: 0

Sheet Apr_sin_filtro
A1: APP | B1: CUENTA_CONTABLE | C1: TIPO_MONEDA | D1: CONCATENADO | E1: Suma de SALDO_FIN_MES | H1: FECHA | I1: CUENTA_CONTABLE | J1: APLICATIVO | K1: TIPO_MONEDA | L1: CONCATENADO | M1: SALDO_FIN_MES
A2: $IM | B2: 14010204000106 | C2: PSS | D2: =_xlfn.CONCAT(B2,C2) -> 14010204000106PSS | E2: 473.82 | H2: 46142 | I2: 21020101000108 | J2: $ST | K2: PSS | L2: =_xlfn.CONCAT(I2,K2) -> 21020101000108PSS | M2: 6.3751367e+09
A3: $IM | B3: 14010204000106 | C3: USD | D3: =_xlfn.CONCAT(B3,C3) -> 14010204000106USD | E3: 160.72 | H3: 46142 | I3: 25041900000223 | J3: CDO | K3: PSS | L3: =_xlfn.CONCAT(I3,K3) -> 25041900000223PSS | M3: -19675648
A4: $IM | B4: 14010301000101 | C4: PSS | D4: =_xlfn.CONCAT(B4,C4) -> 14010301000101PSS | E4: 4528.6 | H4: 46142 | I4: 21020201000111 | J4: $ST | K4: PSS | L4: =_xlfn.CONCAT(I4,K4) -> 21020201000111PSS | M4: 4.2134033e+08
A5: $IM | B5: 14010704000102 | C5: USD | D5: =_xlfn.CONCAT(B5,C5) -> 14010704000102USD | E5: 0 | H5: 46142 | I5: 21010109000107 | J5: $IM | K5: PSS | L5: =_xlfn.CONCAT(I5,K5) -> 21010109000107PSS | M5: 1.9489863e+09
A6: $IM | B6: 14010801000102 | C6: PSS | D6: =_xlfn.CONCAT(B6,C6) -> 14010801000102PSS | E6: 0 | H6: 46142 | I6: 14010406010101 | J6: HPC | K6: USD | L6: =_xlfn.CONCAT(I6,K6) -> 14010406010101USD | M6: 75368250
A7: $IM | B7: 14010804000102 | C7: PSS | D7: =_xlfn.CONCAT(B7,C7) -> 14010804000102PSS | E7: 0 | H7: 46142 | I7: 14011005020101 | J7: FCD | K7: USD | L7: =_xlfn.CONCAT(I7,K7) -> 14011005020101USD | M7: 1.2501852e+08
A8: $IM | B8: 14010804000102 | C8: USD | D8: =_xlfn.CONCAT(B8,C8) -> 14010804000102USD | E8: 271.23 | H8: 46142 | I8: 14011005020102 | J8: FCD | K8: PSS | L8: =_xlfn.CONCAT(I8,K8) -> 14011005020102PSS | M8: 2.0756868e+08
A9: $IM | B9: 14010999010901 | C9: PSS | D9: =_xlfn.CONCAT(B9,C9) -> 14010999010901PSS | E9: 65.34 | H9: 46142 | I9: 21010109000101 | J9: $IM | K9: PSS | L9: =_xlfn.CONCAT(I9,K9) -> 21010109000101PSS | M9: 18815298
A10: $IM | B10: 14010999012102 | C10: USD | D10: =_xlfn.CONCAT(B10,C10) -> 14010999012102USD | E10: 0 | H10: 46142 | I10: 14050306050111 | J10: LIC | K10: PSS | L10: =_xlfn.CONCAT(I10,K10) -> 14050306050111PSS | M10: 42016881
A11: $IM | B11: 14011001000102 | C11: PSS | D11: =_xlfn.CONCAT(B11,C11) -> 14011001000102PSS | E11: 74443818 | H11: 46142 | I11: 14010302010115 | J11: CDO | K11: PSS | L11: =_xlfn.CONCAT(I11,K11) -> 14010302010115PSS | M11: 6105716.8
A12: $IM | B12: 14011004000102 | C12: PSS | D12: =_xlfn.CONCAT(B12,C12) -> 14011004000102PSS | E12: 537360.52 | H12: 46142 | I12: 14050302020112 | J12: CDO | K12: USD | L12: =_xlfn.CONCAT(I12,K12) -> 14050302020112USD | M12: 787161.75
A13: $IM | B13: 14011004000102 | C13: USD | D13: =_xlfn.CONCAT(B13,C13) -> 14011004000102USD | E13: 1607.62 | H13: 46142 | I13: 14011205020102 | J13: FCD | K13: USD | L13: =_xlfn.CONCAT(I13,K13) -> 14011205020102USD | M13: 1602393.4
... A874: MYP | B874: 14051319060101 | C874: PSS | D874: =_xlfn.CONCAT(B874,C874) -> 14051319060101PSS | E874: 1285104.6 | H874: 46142 | I874: 14050306020113 | J874: HPC | K874: USD | L874: =_xlfn.CONCAT(I874,K874) -> 14050306020113USD | M874: 663.2
H875: 46142 | I875: 14010423000114 | J875: HPC | K875: USD | L875: =_xlfn.CONCAT(I875,K875) -> 14010423000114USD | M875: 3084.18
H876: 46142 | I876: 14051306020305 | J876: MYP | K876: PSS | L876: =_xlfn.CONCAT(I876,K876) -> 14051306020305PSS | M876: 48255.2
H877: 46142 | I877: 14010806020104 | J877: LPC | K877: PSS | L877: =_xlfn.CONCAT(I877,K877) -> 14010806020104PSS | M877: 285000000
H878: 46142 | I878: 23030103080101 | J878: MDC | K878: PSS | L878: =_xlfn.CONCAT(I878,K878) -> 23030103080101PSS | M878: 20000000
H879: 46142 | I879: 21020201000105 | J879: $ST | K879: PSS | L879: =_xlfn.CONCAT(I879,K879) -> 21020201000105PSS | M879: 151.82
H880: 46142 | I880: 14011233000106 | J880: LPC | K880: USD | L880: =_xlfn.CONCAT(I880,K880) -> 14011233000106USD | M880: 4758490
H881: 46142 | I881: 14051306020213 | J881: JCC | K881: PSS | L881: =_xlfn.CONCAT(I881,K881) -> 14051306020213PSS | M881: 43112.95
H882: 46142 | I882: 14060206020204 | J882: JCC | K882: PSS | L882: =_xlfn.CONCAT(I882,K882) -> 14060206020204PSS | M882: 6586.84

Sheet Apr_con_filtro
A1: P01_ID_APLI | B1: CUENTA_CONTABLE | C1: TIPO_MONEDA | D1: CONCATENADO | E1: Suma de CUR_BOOK_BAL
A2: $IM | B2: 14010204000106 | C2: PSS | D2: =_xlfn.CONCAT(B2,C2) -> 14010204000106PSS | E2: 473.82
A3: $IM | B3: 14010204000106 | C3: USD | D3: =_xlfn.CONCAT(B3,C3) -> 14010204000106USD | E3: 160.72
A4: $IM | B4: 14010301000101 | C4: PSS | D4: =_xlfn.CONCAT(B4,C4) -> 14010301000101PSS | E4: 4528.6
A5: $IM | B5: 14010704000102 | C5: USD | D5: =_xlfn.CONCAT(B5,C5) -> 14010704000102USD | E5: 0
A6: $IM | B6: 14010801000102 | C6: PSS | D6: =_xlfn.CONCAT(B6,C6) -> 14010801000102PSS | E6: 0
A7: $IM | B7: 14010804000102 | C7: PSS | D7: =_xlfn.CONCAT(B7,C7) -> 14010804000102PSS | E7: 0
A8: $IM | B8: 14010804000102 | C8: USD | D8: =_xlfn.CONCAT(B8,C8) -> 14010804000102USD | E8: 271.23
A9: $IM | B9: 14010999010901 | C9: PSS | D9: =_xlfn.CONCAT(B9,C9) -> 14010999010901PSS | E9: 65.34
A10: $IM | B10: 14010999012101 | C10: USD | D10: =_xlfn.CONCAT(B10,C10) -> 14010999012101USD | E10: 0
A11: $IM | B11: 14010999012102 | C11: USD | D11: =_xlfn.CONCAT(B11,C11) -> 14010999012102USD | E11: 0
A12: $IM | B12: 14011001000102 | C12: PSS | D12: =_xlfn.CONCAT(B12,C12) -> 14011001000102PSS | E12: 74443818
A13: $IM | B13: 14011004000102 | C13: PSS | D13: =_xlfn.CONCAT(B13,C13) -> 14011004000102PSS | E13: 537360.52
... A970: SCF | B970: 71020000000115 | C970: USD | D970: =_xlfn.CONCAT(B970,C970) -> 71020000000115USD | E970: 4309945

Sheet Ajuste_RCD
A1: CTA_CTB | B1: MONEDA | C1: CONCATENADO | D1: Suma de SUM(SALDO_ACTUAL)
A2: 0 | B2: PSS | C2: =_xlfn.CONCAT(A2,B2) -> 0PSS | D2: 0
A3: 0 | B3: USD | C3: =_xlfn.CONCAT(A3,B3) -> 0USD | D3: 0
A4: 13020101010106 | B4: PSS | C4: =_xlfn.CONCAT(A4,B4) -> 13020101010106PSS | D4: 7868114.2
A5: 13020101020103 | B5: USD | C5: =_xlfn.CONCAT(A5,B5) -> 13020101020103USD | D5: -4901562.5
A6: 13030701000101 | B6: PSS | C6: =_xlfn.CONCAT(A6,B6) -> 13030701000101PSS | D6: 115186.1
A7: 13030701000102 | B7: USD | C7: =_xlfn.CONCAT(A7,B7) -> 13030701000102USD | D7: 151643.72
A8: 13030701000103 | B8: USD | C8: =_xlfn.CONCAT(A8,B8) -> 13030701000103USD | D8: 454400
A9: 13030702000101 | B9: PSS | C9: =_xlfn.CONCAT(A9,B9) -> 13030702000101PSS | D9: 148568.51
A10: 13030901000102 | B10: USD | C10: =_xlfn.CONCAT(A10,B10) -> 13030901000102USD | D10: 2.1352211e+08
A11: 13031302000104 | B11: PSS | C11: =_xlfn.CONCAT(A11,B11) -> 13031302000104PSS | D11: 6209213.6
A12: 13031302000105 | B12: PSS | C12: =_xlfn.CONCAT(A12,B12) -> 13031302000105PSS | D12: 75280.71
A13: 13040101010103 | B13: USD | C13: =_xlfn.CONCAT(A13,B13) -> 13040101010103USD | D13: -3026970
... A793: 84040523000001 | B793: PSS | C793: =_xlfn.CONCAT(A793,B793) -> 84040523000001PSS | D793: -324258.89

Sheet Seguimiento
A1: Aplicativo | B1: Tipo de cuadre | C1: Tipo de diferencias | D1: Sustento | E1: Conclusión
A2: MDC | B2: Saldo Contable vs Saldo APR (con filtros) | C2: Diferencias por signo contrario del saldo | D2: Naturaleza contable (provisiones de inversiones): contabilidad en negativo vs finanzas en positivo, mismo monto | E2: Se ajustó el cuadre al ser un comportamiento de la cuenta contable
A3: MDC | B3: Saldo Contable vs Saldo APR (con filtros) | C3: Diferencias por no llegar a la tabla de instrumentos | D3: Falta de configuración de llave APR hacia Common COA, no fluye hacia tablas e instrumentos | E3: Se requiere parametriza el common coa si se requiere que llegue por el APR
A4: MDC | B4: Saldo Finanzas vs Saldo APR (sin filtro) | C4: Diferencias por no llegar a la tabla de instrumentos | D4: Saldos existen en APR pero no llegan a tablas de instrumentos por falta de Common COA | E4: Se requiere parametriza el common coa si se requiere que llegue por el APR
A5: MDC | B5: Saldo Finanzas vs Saldo APR (sin filtro) | C5: Diferenciar por no llegar al APR | D5: Rubros no provienen de Murex (1303, 1309, 1701), solo existen a nivel contable | E5: Se ajustó el cuadre al ser un comportamiento de la cuenta contable
A6: CDO | B6: Saldo Contable/Saldo Finanzas vs Saldo APR c/s filtros | C6: Diferencias por signo del saldo | D6: Naturaleza acreedora: contabilidad en negativo genera aparente descuadre | E6: Se ajustó el cuadre al ser un comportamiento de la cuenta contable
A7: $IM / $ST | B7: Saldo Contable/Saldo Finanzas vs Saldo APR c/s filtros | C7: Diferencias por reclasificación en la contabilidad | D7: Reclasificaciones de rubros 2101 y 2102 hacia 2103 y 2203 | E7: Se ajustó el cuadre al ser un comportamiento de la cuenta contable
A9: Aplicativo | B9: Pendiente
A10: $IM / $ST | B10: Revisar diferencias remanentes, consultar con contabilidad por qué no llega por ajuste rcd la reclasificación
A11: CDO | B11: Diferencias remanentes
A12: WBC | B12: Consultar por cuentas contables 7 - contigentes
A13: LPC | B13: Diferencias por no llegar en APR, pero sí figura en Saldos Finanzas
